Workbook
Name INST: [1]instrucciones!$B$1:$O$48
Name PORT: [2]formato!$A$6:$N$68

Sheet Instructions
B2: World Cup 2026 "Quiniela" Prediction League
B4: INSTRUCTIONS
B5: 1. Go to the "Group Stage Predictions" sheet and enter your predicted scores in the grey cells for every group-stage match.
B6: 2. Go to the "Knock-Out Predictions" sheet and enter your knock-out picks in the grey cells. Make sure to use the official FIFA three-letter codes shown here.
B7: 3. Add your name and team name in the "Knock-Out Predictions" sheet and return the completed Excel doc to rasherrington@gmail.com.
B9: SCORING
B10: The player with the highest score at the end of the tournament | G10: COMPETITORS
B11: will be crowned champion! Scoring is a little different this year…
F12: GROUP A | H12: GROUP G
B13: Group stage scoring | E13: MEX | F13: Mexico (MEX) | H13: Belgium (BEL) | I13: BEL
C14: Points | E14: RSA | F14: South Africa (RSA) | H14: Egypt (EGY) | I14: EGY
B15: Exact scoreline | C15: 4 | E15: KOR | F15: Korea Republic (KOR) | H15: Iran (IRN) | I15: IRN
B16: Correct result and correct goal difference | C16: 2 | E16: CZE | F16: Czechia (CZE) | H16: New Zealand (NZL) | I16: NZL
B17: Correct result only | C17: 1
B18: Incorrect result | C18: 0 | F18: GROUP B | H18: GROUP H
E19: CAN | F19: Canada (CAN) | H19: Spain (ESP) | I19: ESP
B20: Knock-out stage scoring | E20: BIH | F20: Bosnia and Herzegovina (BIH) | H20: Cape Verde (CPV) | I20: CPV
C21: Points per correct team | E21: QAT | F21: Qatar (QAT) | H21: Saudi Arabia (KSA) | I21: KSA
B22: Round of 32 | C22: 2 | E22: SUI | F22: Switzerland (SUI) | H22: Uruguay (URU) | I22: URU
B23: Round of 16 | C23: 4
B24: Quarter-final | C24: 6 | F24: GROUP C | H24: GROUP I
B25: Semi-final | C25: 9 | E25: BRA | F25: Brazil (BRA) | H25: France (FRA) | I25: FRA
B26: Finalist | C26: 14 | E26: MAR | F26: Morocco (MAR) | H26: Senegal (SEN) | I26: SEN
B27: Champion | C27: 25 | E27: HAI | F27: Haiti (HAI) | H27: Iraq (IRQ) | I27: IRQ
E28: SCO | F28: Scotland (SCO) | H28: Norway (NOR) | I28: NOR
F30: GROUP D | H30: GROUP J
E31: USA | F31: USA | H31: Argentina (ARG) | I31: ARG
E32: PAR | F32: Paraguay (PAR) | H32: Algeria (ALG) | I32: ALG
E33: AUS | F33: Australia (AUS) | H33: Austria (AUT) | I33: AUT
E34: TUR | F34: Türkiye (TUR) | H34: Jordan (JOR) | I34: JOR
F36: GROUP E | H36: GROUP K
E37: GER | F37: Germany (GER) | H37: Portugal (POR) | I37: POR
E38: CUW | F38: Curaçao (CUW) | H38: DR Congo (COD) | I38: COD
E39: CIV | F39: Côte d'Ivoire (CIV) | H39: Uzbekistan (UZB) | I39: UZB
E40: ECU | F40: Ecuador (ECU) | H40: Colombia (COL) | I40: COL
F42: GROUP F | H42: GROUP L
E43: NED | F43: Netherlands (NED) | H43: England (ENG) | I43: ENG
E44: JPN | F44: Japan (JPN) | H44: Croatia (CRO) | I44: CRO
E45: SWE | F45: Sweden (SWE) | H45: Ghana (GHA) | I45: GHA
E46: TUN | F46: Tunisia (TUN) | H46: Panama (PAN) | I46: PAN

Sheet Group Stage Predictions
B2: Instructions
B3: 1. Enter your score predictions in the grey cells. The sheet will calculate your predicted group rankings | AA3: VS OPPONENTS
B4: 2. Once you have completed the group stage predictions, move to 'Knock-Out Predictions' where the Last 32 will have been automatically populated (including which 3rd place teams advance) based on your predictions below.
Z5: POINTS | AD5: DG x 10 + GF vs otro 1 x 1 | AH5: Pts x 10,000 + DG x 100 + GF vs otros 2 x 2 | AL5: -0.5 / +0.5 tie-break adjustment | AP5: TRUE if teams are tied on points, GF and GA in all combinations | BB5: if still tied, check head-to-head
B6: Group A | S6: AJ | T6: AK | U6: AL | V6: AM | W6: AN | X6: AO | Y6: AP | Z6: AQ | AA6: AR | AB6: AS | AC6: AT | AD6: AU | AE6: AV | AF6: AW | AG6: AX | AH6: AY | AI6: AZ | AJ6: BA | AK6: BB | AL6: BC | AM6: BD | AN6: BE | AO6: BF | AP6: BG | AQ6: BH | AR6: BI | AS6: BJ | AT6: BK | AU6: BL | AV6: BM | AW6: BN | AX6: BO | AY6: BP | AZ6: BO | BA6: BP | BC6: =IF($AU8,IF(E7-G7<0,-0.5,IF(G7-E7<0,0.5,0)),IF($AQ8,IF($AH8>$AH9,-0.5,IF($AH8<$AH9,0.5,0)),IF($AR8,IF($AI8>$AI9,-0.5, IF($AI8<$AI9,0.5,0)),0))) -> 0 | BE6: =G11-E11 -> 1
B7: 46184.542 | C7: Mexico City | D7: =+Instructions!F13 -> Mexico (MEX) | E7: 1 | F7: =+Instructions!F14 -> South Africa (RSA) | G7: 0 | K7: Group A | L7: Pts | M7: GF | N7: GA | O7: GD | S7: sort low to high | T7: Rank | U7: Team | V7: Pts | W7: GF | X7: GC | Y7: DG | Z7: Ag1 | AA7: Ag2 | AB7: Ag3 | AC7: Ag4 | AD7: Sp1 | AE7: Sp2 | AF7: Sp3 | AG7: Sp4 | AH7: T123 | AI7: T124 | AJ7: T134 | AK7: T234 | AL7: Rk1 | AM7: Rk2 | AN7: Rk3 | AO7: Rk4 | AP7: T1234 | AQ7: T123 | AR7: T124 | AS7: T134 | AT7: T234 | AU7: T12 | AV7: T13 | AW7: T14 | AX7: T23 | AY7: T24 | AZ7: T34 | BA7: NoT | BB7: sRk1 | BC7: sRk2 | BD7: sRk3 | BE7: sRk4
B8: 46184.833 | C8: Guadalajara | D8: =+Instructions!F15 -> Korea Republic (KOR) | E8: 0 | F8: =+Instructions!F16 -> Czechia (CZE) | G8: 0 | J8: =Q8 -> 1 | K8: {=INDEX(U8:U11,MATCH(S8,$T8:$T11,0))} -> MEX | L8: {=INDEX(V8:V11,MATCH(S8,$T8:$T11,0))} -> 9 | M8: {=INDEX(W8:W11,MATCH(S8,$T8:$T11,0))} -> 3 | N8: {=INDEX(X8:X11,MATCH(S8,$T8:$T11,0))} -> 0 | O8: {=INDEX(Y8:Y11,MATCH(S8,$T8:$T11,0))} -> 3 | Q8: 1 | R8: =ROUND(S8,0) -> 1 | S8: =+SMALL(T8:T11,1) -> 0.95 | T8: =SUM(AL8:AO8)+2.45 -> 0.95 | U8: =+Instructions!E13 -> MEX | V8: =SUM(Z8:AC8) -> 9 | W8: =E7+E9+G11 -> 3 | X8: =G7+G9+E11 -> 0 | Y8: =W8-X8 -> 3 | Z8: x | AA8: =IF(ISBLANK(E7),0,IF(E7>G7,3,IF(E7=G7,1,0))) -> 3 | AB8: =IF(ISBLANK(E9),0,IF(E9>G9,3,IF(E9=G9,1,0))) -> 3 | AC8: =IF(ISBLANK(G11),0,IF(G11>E11,3,IF(G11=E11,1,0))) -> 3 | AD8: x | AE8: =(10*(Y8-Y9)+W8-W9>0) -> TRUE | AF8: =10*(Y8-Y10)+W8-W10>0 -> TRUE | AG8: =10*(Y8-Y11)+W8-W11>0 -> TRUE | AH8: =10000*(AA8+AB8)+(E9-G9+E7-G7)*100+(E9+E7) -> 60202 | AI8: =10000*(AA8+AC8)+(E7-G7+G11-E11)*100+(E7+G11) -> 60202 | AJ8: =10000*(AB8+AC8)+(E9-G9+G11-E11)*100+(E9+G11) -> 60202 | AK8: x | AL8: x | AM8: =IF($V8>$V9,-0.5,IF($V9>$V8,0.5,IF(AE8,-0.5,IF(AD9,0.5,BC8)))) -> -0.5 | AN8: =IF($V8>$V10,-0.5,IF($V10>$V8,0.5,IF(AF8,-0.5,IF(AD10,0.5,BD8)))) -> -0.5 | AO8: =IF($V8>$V11,-0.5,IF($V11>$V8,0.5,IF(AG8,-0.5,IF(AD11,0.5,BE8)))) -> -0.5 | AP8: =AND(AND(V8=V9,V9=V10,V10=V11),AND(W8=W9,W9=W10,W10=W11),AND(X8=X9,X9=X10,X10=X11)) -> FALSE | AQ8: =AND(NOT(AP8),V8=V9,V8=V10,W8=W9,W8=W10,X8=X9,X8=X10) -> FALSE | AR8: =AND(NOT(AP8),V8=V9,V8=V11,W8=W9,W8=W11,X8=X9,X8=X11) -> FALSE | AS8: =AND(NOT(AP8),V8=V10,V8=V11,W8=W10,W8=W11,X8=X10,X8=X11) -> FALSE | AT8: =AND(NOT(AP8),V9=V10,V9=V11,W9=W10,W9=W11,X9=X10,X9=X11) -> FALSE | AU8: =AND(NOT(AP8),NOT(AQ8),NOT(AR8),V8=V9,W8=W9,X8=X9) -> FALSE | AV8: =AND(NOT(AP8),NOT(AQ8),NOT(AS8),V8=V10,W8=W10,X8=X10) -> FALSE | AW8: =AND(NOT(AP8),NOT(AR8),NOT(AS8),V8=V11,W8=W11,X8=X11) -> FALSE | AX8: =AND(NOT(AP8),NOT(AQ8),NOT(AT8),V9=V10,W9=W10) -> FALSE | AY8: =AND(NOT(AP8),NOT(AR8),NOT(AT8),V9=V11,W9=W11,X9=X11) -> FALSE | AZ8: =AND(NOT(AP8),NOT(AS8),NOT(AT8),V10=V11,W10=W11,X10=X11) -> FALSE | BA8: {=AND(NOT(AP8:AZ8))} -> TRUE | BB8: x | BC8: =IF($AU8,IF(G7-E7<0,-0.5,IF(E7-G7<0,0.5,0)),IF($AQ8,IF($AH8>$AH9,-0.5,IF($AH8<$AH9,0.5,0)),IF($AR8,IF($AI8>$AI9,-0.5, IF($AI8<$AI9,0.5,0)),0))) -> 0 | BD8: =IF($AV8,IF(G9-E9<0,-0.5,IF(E9-G9<0,0.5,0)),IF($AQ8,IF($AH8>$AH10,-0.5,IF($AH8<$AH10,0.5,0)),IF($AS8,IF($AJ8>$AJ10,-0.5,IF($AJ8<$AJ10,0.5,0)),0))) -> 0 | BE8: =IF($AW8,IF(E11-G11<0,-0.5,IF(G11-E11<0,0.5,0)),IF($AR8,IF($AI8>$AI11,-0.5,IF($AI8<$AI11,0.5,0)),IF($AS8,IF($AJ8>$AJ11,-0.5, IF($AJ8<$AJ11,0.5,0)),0))) -> 0
B9: 46191.792 | C9: Guadalajara | D9: =+Instructions!F13 -> Mexico (MEX) | E9: 1 | F9: =+Instructions!F15 -> Korea Republic (KOR) | G9: 0 | J9: =Q9 -> 2 | K9: {=INDEX(U8:U11,MATCH(S9,$T8:$T11,0))} -> KOR | L9: {=INDEX(V8:V11,MATCH(S9,$T8:$T11,0))} -> 4 | M9: {=INDEX(W8:W11,MATCH(S9,$T8:$T11,0))} -> 1 | N9: {=INDEX(X8:X11,MATCH(S9,$T8:$T11,0))} -> 1 | O9: {=INDEX(Y8:Y11,MATCH(S9,$T8:$T11,0))} -> 0 | Q9: =IF(ROUND(S9,0)=ROUND(S8,0),Q8,2) -> 2 | R9: =ROUND(S9,0) -> 2 | S9: =+SMALL(T8:T11,2) -> 1.97 | T9: =SUM(AL9:AO9)+2.46 -> 3.96 | U9: =+Instructions!E14 -> RSA | V9: =SUM(Z9:AC9) -> 1 | W9: =G7+G10+E12 -> 0 | X9: =E7+E10+G12 -> 2 | Y9: =W9-X9 -> -2 | Z9: =IF(ISBLANK(G7),0,IF(AA8=3,0,IF(AA8=1,1,3))) -> 0 | AA9: x | AB9: =IF(ISBLANK(E12),0,IF(AA10=3,0,IF(AA10=1,1,3))) -> 0 | AC9: =IF(ISBLANK(G10),0,IF(G10>E10,3,IF(G10=E10,1,0))) -> 1 | AD9: =(10*(Y8-Y9)+W8-W9<0) -> FALSE | AE9: x | AF9: =10*(Y9-Y10)+W9-W10>0 -> FALSE | AG9: =10*(Y9-Y11)+W9-W11>0 -> FALSE | AH9: =10000*(Z9+AB9)+(G7-E7+E12-G12)*100+(G7+E12) -> -200 | AI9: =10000*(Z9+AC9)+(G7-E7+G10-E10)*100+(G7+G10) -> 9900 | AJ9: x | AK9: =10000*(AB9+AC9)+(G10-E10+E12-G12)*100+(G10+E12) -> 9900 | AL9: =-AM8 -> 0.5 | AM9: x | AN9: =IF($V9>$V10,-0.5,IF($V10>$V9,0.5,IF(AF9,-0.5,IF(AE10,0.5,BD9)))) -> 0.5 | AO9: =IF($V9>$V11,-0.5,IF($V11>$V9,0.5,IF(AG9,-0.5,IF(AE11,0.5,BE9)))) -> 0.5 | BC9: x | BD9: =IF($AX8,IF(G12-E12<0,-0.5,IF(E12-G12<0,0.5,0)),IF($AQ8,IF($AH9>$AH10,-0.5,IF($AH9<$AH10,0.5,0)),IF($AT8,IF($AK9>$AK10,-0.5,IF($AK9<$AK10,0.5,0)),0))) -> 0 | BE9: =IF($AY8,IF(E10-G10<0,-0.5,IF(G10-E10<0,0.5,0)),IF($AR8,IF($AI9>$AI11,-0.5,IF($AI9<$AI11,0.5,0)),IF($AT8,IF($AK9>$AK11,-0.5,IF($AK9<$AK11,0.5,0)),0))) -> 0
B10: 46191.417 | C10: Atlanta | D10: =+Instructions!F16 -> Czechia (CZE) | E10: 0 | F10: =+Instructions!F14 -> South Africa (RSA) | G10: 0 | J10: =Q10 -> 3 | K10: {=INDEX(U8:U11,MATCH(S10,$T8:$T11,0))} -> CZE | L10: {=INDEX(V8:V11,MATCH(S10,$T8:$T11,0))} -> 2 | M10: {=INDEX(W8:W11,MATCH(S10,$T8:$T11,0))} -> 0 | N10: {=INDEX(X8:X11,MATCH(S10,$T8:$T11,0))} -> 1 | O10: {=INDEX(Y8:Y11,MATCH(S10,$T8:$T11,0))} -> -1 | Q10: =IF(ROUND(S10,0)=ROUND(S9,0),Q9,3) -> 3 | R10: =ROUND(S10,0) -> 3 | S10: =+SMALL(T8:T11,3) -> 2.98 | T10: =SUM(AL10:AO10)+2.47 -> 1.97 | U10: =+Instructions!E15 -> KOR | V10: =SUM(Z10:AC10) -> 4 | W10: =E8+G9+G12 -> 1 | X10: =G8+E9+E12 -> 1 | Y10: =W10-X10 -> 0 | Z10: =IF(ISBLANK(G9),0,IF(AB8=3,0,IF(AB8=1,1,3))) -> 0 | AA10: =IF(ISBLANK(G12),0,IF(G12>E12,3,IF(G12=E12,1,0))) -> 3 | AB10: x | AC10: =IF(ISBLANK(E8),0,IF(E8>G8,3,IF(E8=G8,1,0))) -> 1 | AD10: =10*(Y8-Y10)+W8-W10<0 -> FALSE | AE10: =10*(Y9-Y10)+W9-W10<0 -> TRUE | AF10: x | AG10: =10*(Y10-Y11)+W10-W11>0 -> TRUE | AH10: =10000*(Z10+AA10)+(G9-E9+G12-E12)*100+(G9+G12) -> 30001 | AI10: x | AJ10: =10000*(Z10+AC10)+(E8-G8+G9-E9)*100+(E8+G9) -> 9900 | AK10: =10000*(AA10+AC10)+(E8-G8+G12-E12)*100+(E8+G12) -> 40101 | AL10: =-AN8 -> 0.5 | AM10: =-AN9 -> -0.5 | AN10: x | AO10: =IF($V10>$V11,-0.5,IF($V11>$V10,0.5,IF(AG10,-0.5,IF(AF11,0.5,BE10)))) -> -0.5 | BD10: x | BE10: =IF($AZ8,IF(G8-E8<0,-0.5,IF(E8-G8<0,0.5,0)),IF($AS8,IF($AJ10>$AJ11,-0.5,IF($AJ10<$AJ11,0.5,0)),IF($AT8,IF($AK10>$AK11,-0.5,IF($AK10<$AK11,0.5,0)),0))) -> 0
B11: 46197.792 | C11: Mexico City | D11: =+Instructions!F16 -> Czechia (CZE) | E11: 0 | F11: =+Instructions!F13 -> Mexico (MEX) | G11: 1 | J11: =Q11 -> 4 | K11: {=INDEX(U8:U11,MATCH(S11,$T8:$T11,0))} -> RSA | L11: {=INDEX(V8:V11,MATCH(S11,$T8:$T11,0))} -> 1 | M11: {=INDEX(W8:W11,MATCH(S11,$T8:$T11,0))} -> 0 | N11: {=INDEX(X8:X11,MATCH(S11,$T8:$T11,0))} -> 2 | O11: {=INDEX(Y8:Y11,MATCH(S11,$T8:$T11,0))} -> -2 | Q11: =IF(ROUND(S11,0)=ROUND(S10,0),Q10,4) -> 4 | R11: =ROUND(S11,0) -> 4 | S11: =+SMALL(T8:T11,4) -> 3.96 | T11: =SUM(AL11:AO11)+2.48 -> 2.98 | U11: =+Instructions!E16 -> CZE | V11: =SUM(Z11:AC11) -> 2 | W11: =G8+E10+E11 -> 0 | X11: =E8+G10+G11 -> 1 | Y11: =W11-X11 -> -1 | Z11: =IF(ISBLANK(E11),0,IF(AC8=3,0,IF(AC8=1,1,3))) -> 0 | AA11: =IF(ISBLANK(E10),0,IF(AC9=3,0,IF(AC9=1,1,3))) -> 1 | AB11: =IF(ISBLANK(G8),0,IF(AC10=3,0,IF(AC10=1,1,3))) -> 1 | AC11: x | AD11: =10*(Y8-Y11)+W8-W11<0 -> FALSE | AE11: =10*(Y9-Y11)+W9-W11<0 -> TRUE | AF11: =10*(Y10-Y11)+W10-W11<0 -> FALSE | AG11: x | AH11: x | AI11: =10000*(Z11+AA11)+(E11-G11+E10-G10)*100+(E11+E10) -> 9900 | AJ11: =10000*(Z11+AB11)+(G8-E8+E11-G11)*100+(G8+E11) -> 9900 | AK11: =10000*(AA11+AB11)+(E10-G10+G8-E8)*100+(E10+G8) -> 20000 | AL11: =-AO8 -> 0.5 | AM11: =-AO9 -> -0.5 | AN11: =-AO10 -> 0.5 | AO11: x | BE11: x
B12: 46197.792 | C12: Monterrey | D12: =+Instructions!F14 -> South Africa (RSA) | E12: 0 | F12: =+Instructions!F15 -> Korea Republic (KOR) | G12: 1 | K12: =IF(ISBLANK(G12)," ",+IF(OR(J10<3,J9<2),"TIE BREAK! Pick your qualifiers on the Knock-Out Predictions sheet"," "))
B14: Group B
B15: 46185.542 | C15: Toronto | D15: =+Instructions!F19 -> Canada (CAN) | E15: 1 | F15: =+Instructions!F20 -> Bosnia and Herzegovina (BIH) | G15: 0 | K15: Group B | L15: Pts | M15: GF | N15: GA | O15: GD | T15: Rank | U15: Team | V15: Pts | W15: GF | X15: GC | Y15: DG | Z15: Ag1 | AA15: Ag2 | AB15: Ag3 | AC15: Ag4 | AD15: Sp1 | AE15: Sp2 | AF15: Sp3 | AG15: Sp4 | AH15: T123 | AI15: T124 | AJ15: T134 | AK15: T234 | AL15: Rk1 | AM15: Rk2 | AN15: Rk3 | AO15: Rk4 | AP15: T1234 | AQ15: T123 | AR15: T124 | AS15: T134 | AT15: T234 | AU15: T12 | AV15: T13 | AW15: T14 | AX15: T23 | AY15: T24 | AZ15: T34 | BA15: NoT | BB15: sRk1 | BC15: sRk2 | BD15: sRk3 | BE15: sRk4
B16: 46186.542 | C16: San Francisco | D16: =+Instructions!F21 -> Qatar (QAT) | E16: 0 | F16: =+Instructions!F22 -> Switzerland (SUI) | G16: 2 | J16: =Q16 -> 1 | K16: {=INDEX(U16:U19,MATCH(S16,$T16:$T19,0))} -> SUI | L16: {=INDEX(V16:V19,MATCH(S16,$T16:$T19,0))} -> 9 | M16: {=INDEX(W16:W19,MATCH(S16,$T16:$T19,0))} -> 4 | N16: {=INDEX(X16:X19,MATCH(S16,$T16:$T19,0))} -> 0 | O16: {=INDEX(Y16:Y19,MATCH(S16,$T16:$T19,0))} -> 4 | Q16: 1 | R16: =ROUND(S16,0) -> 1 | S16: =+SMALL(T16:T19,1) -> 0.98 | T16: =SUM(AL16:AO16)+2.45 -> 1.95 | U16: =+Instructions!E19 -> CAN | V16: =SUM(Z16:AC16) -> 6 | W16: =E15+E17+G19 -> 2 | X16: =G15+G17+E19 -> 1 | Y16: =W16-X16 -> 1 | Z16: x | AA16: =IF(ISBLANK(E15),0,IF(E15>G15,3,IF(E15=G15,1,0))) -> 3 | AB16: =IF(ISBLANK(E17),0,IF(E17>G17,3,IF(E17=G17,1,0))) -> 3 | AC16: =IF(ISBLANK(G19),0,IF(G19>E19,3,IF(G19=E19,1,0))) -> 0 | AD16: x | AE16: =(10*(Y16-Y17)+W16-W17>0) -> TRUE | AF16: =10*(Y16-Y18)+W16-W18>0 -> TRUE | AG16: =10*(Y16-Y19)+W16-W19>0 -> FALSE | AH16: =10000*(AA16+AB16)+(E17-G17+E15-G15)*100+(E17+E15) -> 60202 | AI16: =10000*(AA16+AC16)+(E15-G15+G19-E19)*100+(E15+G19) -> 30001 | AJ16: =10000*(AB16+AC16)+(G19-E19+E17-G17)*100+(G19+E17) -> 30001 | AK16: x | AL16: x | AM16: =IF($V16>$V17,-0.5,IF($V17>$V16,0.5,IF(AE16,-0.5,IF(AD17,0.5,BC16)))) -> -0.5 | AN16: =IF($V16>$V18,-0.5,IF($V18>$V16,0.5,IF(AF16,-0.5,IF(AD18,0.5,BD16)))) -> -0.5 | AO16: =IF($V16>$V19,-0.5,IF($V19>$V16,0.5,IF(AG16,-0.5,IF(AD19,0.5,BE16)))) -> 0.5 | AP16: =AND(AND(V16=V17,V17=V18,V18=V19),AND(W16=W17,W17=W18,W18=W19),AND(X16=X17,X17=X18,X18=X19)) -> FALSE | AQ16: =AND(NOT(AP16),V16=V17,V16=V18,W16=W17,W16=W18,X16=X17,X16=X18) -> FALSE | AR16: =AND(NOT(AP16),V16=V17,V16=V19,W16=W17,W16=W19,X16=X17,X16=X19) -> FALSE | AS16: =AND(NOT(AP16),V16=V18,V16=V19,W16=W18,W16=W19,X16=X18,X16=X19) -> FALSE | AT16: =AND(NOT(AP16),V17=V18,V17=V19,W17=W18,W17=W19,X17=X18,X17=X19) -> FALSE | AU16: =AND(NOT(AP16),NOT(AQ16),NOT(AR16),V16=V17,W16=W17,X16=X17) -> FALSE | AV16: =AND(NOT(AP16),NOT(AQ16),NOT(AS16),V16=V18,W16=W18,X16=X18) -> FALSE | AW16: =AND(NOT(AP16),NOT(AR16),NOT(AS16),V16=V19,W16=W19,X16=X19) -> FALSE | AX16: =AND(NOT(AP16),NOT(AQ16),NOT(AT16),V17=V18,W17=W18) -> FALSE | AY16: =AND(NOT(AP16),NOT(AR16),NOT(AT16),V17=V19,W17=W19,X17=X19) -> FALSE | AZ16: =AND(NOT(AP16),NOT(AS16),NOT(AT16),V18=V19,W18=W19,X18=X19) -> FALSE | BA16: {=AND(NOT(AP16:AZ16))} -> TRUE | BB16: x | BC16: =IF($AU16,IF(G15-E15<0,-0.5,IF(E15-G15<0,0.5,0)),IF($AQ16,IF($AH16>$AH17,-0.5,IF($AH16<$AH17,0.5,0)),IF($AR16,IF($AI16>$AI17,-0.5, IF($AI16<$AI17,0.5,0)),0))) -> 0 | BD16: =IF($AV16,IF(G17-E17<0,-0.5,IF(E17-G17<0,0.5,0)),IF($AQ16,IF($AH16>$AH18,-0.5,IF($AH16<$AH18,0.5,0)),IF($AS16,IF($AJ16>$AJ18,-0.5,IF($AJ16<$AJ18,0.5,0)),0))) -> 0 | BE16: =IF($AW16,IF(E19-G19<0,-0.5,IF(G19-E19<0,0.5,0)),IF($AR16,IF($AI16>$AI19,-0.5,IF($AI16<$AI19,0.5,0)),IF($AS16,IF($AJ16>$AJ19,-0.5, IF($AJ16<$AJ19,0.5,0)),0))) -> 0
B17: 46191.667 | C17: Vancouver | D17: =+Instructions!F19 -> Canada (CAN) | E17: 1 | F17: =+Instructions!F21 -> Qatar (QAT) | G17: 0 | J17: =Q17 -> 2 | K17: {=INDEX(U16:U19,MATCH(S17,$T16:$T19,0))} -> CAN | L17: {=INDEX(V16:V19,MATCH(S17,$T16:$T19,0))} -> 6 | M17: {=INDEX(W16:W19,MATCH(S17,$T16:$T19,0))} -> 2 | N17: {=INDEX(X16:X19,MATCH(S17,$T16:$T19,0))} -> 1 | O17: {=INDEX(Y16:Y19,MATCH(S17,$T16:$T19,0))} -> 1 | Q17: =IF(ROUND(S17,0)=ROUND(S16,0),Q16,2) -> 2 | R17: =ROUND(S17,0) -> 2 | S17: =+SMALL(T16:T19,2) -> 1.95 | T17: =SUM(AL17:AO17)+2.46 -> 2.96 | U17: =+Instructions!E20 -> BIH | V17: =SUM(Z17:AC17) -> 3 | W17: =G15+G18+E20 -> 1 | X17: =E15+E18+G20 -> 2 | Y17: =W17-X17 -> -1 | Z17: =IF(ISBLANK(G15),0,IF(AA16=3,0,IF(AA16=1,1,3))) -> 0 | AA17: x | AB17: =IF(ISBLANK(E20),0,IF(AA18=3,0,IF(AA18=1,1,3))) -> 3 | AC17: =IF(ISBLANK(G18),0,IF(G18>E18,3,IF(G18=E18,1,0))) -> 0 | AD17: =(10*(Y16-Y17)+W16-W17<0) -> FALSE | AE17: x | AF17: =10*(Y17-Y18)+W17-W18>0 -> TRUE | AG17: =10*(Y17-Y19)+W17-W19>0 -> FALSE | AH17: =10000*(Z17+AB17)+(G15-E15+E20-G20)*100+(G15+E20) -> 30001 | AI17: =10000*(Z17+AC17)+(G15-E15+G18-E18)*100+(G15+G18) -> -200 | AJ17: x | AK17: =10000*(AB17+AC17)+(G18-E18+E20-G20)*100+(G18+E20) -> 30001 | AL17: =-AM16 -> 0.5 | AM17: x | AN17: =IF($V17>$V18,-0.5,IF($V18>$V17,0.5,IF(AF17,-0.5,IF(AE18,0.5,BD17)))) -> -0.5 | AO17: =IF($V17>$V19,-0.5,IF($V19>$V17,0.5,IF(AG17,-0.5,IF(AE19,0.5,BE17)))) -> 0.5 | BC17: x | BD17: =IF($AX16,IF(G20-E20<0,-0.5,IF(E20-G20<0,0.5,0)),IF($AQ16,IF($AH17>$AH18,-0.5,IF($AH17<$AH18,0.5,0)),IF($AT16,IF($AK17>$AK18,-0.5,IF($AK17<$AK18,0.5,0)),0))) -> 0 | BE17: =IF($AY16,IF(E18-G18<0,-0.5,IF(G18-E18<0,0.5,0)),IF($AR16,IF($AI17>$AI19,-0.5,IF($AI17<$AI19,0.5,0)),IF($AT16,IF($AK17>$AK19,-0.5,IF($AK17<$AK19,0.5,0)),0))) -> 0
B18: 46191.542 | C18: Los Angeles | D18: =+Instructions!F22 -> Switzerland (SUI) | E18: 1 | F18: =+Instructions!F20 -> Bosnia and Herzegovina (BIH) | G18: 0 | J18: =Q18 -> 3 | K18: {=INDEX(U16:U19,MATCH(S18,$T16:$T19,0))} -> BIH | L18: {=INDEX(V16:V19,MATCH(S18,$T16:$T19,0))} -> 3 | M18: {=INDEX(W16:W19,MATCH(S18,$T16:$T19,0))} -> 1 | N18: {=INDEX(X16:X19,MATCH(S18,$T16:$T19,0))} -> 2 | O18: {=INDEX(Y16:Y19,MATCH(S18,$T16:$T19,0))} -> -1 | Q18: =IF(ROUND(S18,0)=ROUND(S17,0),Q17,3) -> 3 | R18: =ROUND(S18,0) -> 3 | S18: =+SMALL(T16:T19,3) -> 2.96 | T18: =SUM(AL18:AO18)+2.47 -> 3.97 | U18: =+Instructions!E21 -> QAT | V18: =SUM(Z18:AC18) -> 0 | W18: =E16+G17+G20 -> 0 | X18: =G16+E17+E20 -> 4 | Y18: =W18-X18 -> -4 | Z18: =IF(ISBLANK(G17),0,IF(AB16=3,0,IF(AB16=1,1,3))) -> 0 | AA18: =IF(ISBLANK(G20),0,IF(G20>E20,3,IF(G20=E20,1,0))) -> 0 | AB18: x | AC18: =IF(ISBLANK(E16),0,IF(E16>G16,3,IF(E16=G16,1,0))) -> 0 | AD18: =10*(Y16-Y18)+W16-W18<0 -> FALSE | AE18: =10*(Y17-Y18)+W17-W18<0 -> FALSE | AF18: x | AG18: =10*(Y18-Y19)+W18-W19>0 -> FALSE | AH18: =10000*(Z18+AA18)+(G17-E17+G20-E20)*100+(G17+G20) -> -200 | AI18: x | AJ18: =10000*(Z18+AC18)+(E16-G16+G17-E17)*100+(E16+G17) -> -300 | AK18: =10000*(AA18+AC18)+(E16-G16+G20-E20)*100+(E16+G20) -> -300 | AL18: =-AN16 -> 0.5 | AM18: =-AN17 -> 0.5 | AN18: x | AO18: =IF($V18>$V19,-0.5,IF($V19>$V18,0.5,IF(AG18,-0.5,IF(AF19,0.5,BE18)))) -> 0.5 | BD18: x | BE18: =IF($AZ16,IF(G16-E16<0,-0.5,IF(E16-G16<0,0.5,0)),IF($AS16,IF($AJ18>$AJ19,-0.5,IF($AJ18<$AJ19,0.5,0)),IF($AT16,IF($AK18>$AK19,-0.5,IF($AK18<$AK19,0.5,0)),0))) -> 0
B19: 46197.542 | C19: Vancouver | D19: =+Instructions!F22 -> Switzerland (SUI) | E19: 1 | F19: =+Instructions!F19 -> Canada (CAN) | G19: 0 | J19: =Q19 -> 4 | K19: {=INDEX(U16:U19,MATCH(S19,$T16:$T19,0))} -> QAT | L19: {=INDEX(V16:V19,MATCH(S19,$T16:$T19,0))} -> 0 | M19: {=INDEX(W16:W19,MATCH(S19,$T16:$T19,0))} -> 0 | N19: {=INDEX(X16:X19,MATCH(S19,$T16:$T19,0))} -> 4 | O19: {=INDEX(Y16:Y19,MATCH(S19,$T16:$T19,0))} -> -4 | Q19: =IF(ROUND(S19,0)=ROUND(S18,0),Q18,4) -> 4 | R19: =ROUND(S19,0) -> 4 | S19: =+SMALL(T16:T19,4) -> 3.97 | T19: =SUM(AL19:AO19)+2.48 -> 0.98 | U19: =+Instructions!E22 -> SUI | V19: =SUM(Z19:AC19) -> 9 | W19: =G16+E18+E19 -> 4 | X19: =E16+G18+G19 -> 0 | Y19: =W19-X19 -> 4 | Z19: =IF(ISBLANK(E19),0,IF(AC16=3,0,IF(AC16=1,1,3))) -> 3 | AA19: =IF(ISBLANK(E18),0,IF(AC17=3,0,IF(AC17=1,1,3))) -> 3 | AB19: =IF(ISBLANK(G16),0,IF(AC18=3,0,IF(AC18=1,1,3))) -> 3 | AC19: x | AD19: =10*(Y16-Y19)+W16-W19<0 -> TRUE | AE19: =10*(Y17-Y19)+W17-W19<0 -> TRUE | AF19: =10*(Y18-Y19)+W18-W19<0 -> TRUE | AG19: x | AH19: x | AI19: =10000*(Z19+AA19)+(E18-G18+E19-G19)*100+(E18+E19) -> 60202 | AJ19: =10000*(Z19+AB19)+(E19-G19+G16-E16)*100+(E19+G16) -> 60303 | AK19: =10000*(AA19+AB19)+(E18-G18+G16-E16)*100+(E18+G16) -> 60303 | AL19: =-AO16 -> -0.5 | AM19: =-AO17 -> -0.5 | AN19: =-AO18 -> -0.5 | AO19: x | BE19: x
B20: 46197.542 | C20: Seattle | D20: =+Instructions!F20 -> Bosnia and Herzegovina (BIH) | E20: 1 | F20: =+Instructions!F21 -> Qatar (QAT) | G20: 0 | K20: =IF(ISBLANK(G20)," ",+IF(OR(J18<3,J17<2),"TIE BREAK! Pick your qualifiers on the Knock-Out Predictions sheet"," "))
B22: Group C
B23: 46186.667 | C23: New Jersey | D23: =+Instructions!F25 -> Brazil (BRA) | E23: 1 | F23: =+Instructions!F26 -> Morocco (MAR) | G23: 0 | K23: Group C | L23: Pts | M23: GF | N23: GA | O23: GD | T23: Rank | U23: Team | V23: Pts | W23: GF | X23: GC | Y23: DG | Z23: Ag1 | AA23: Ag2 | AB23: Ag3 | AC23: Ag4 | AD23: Sp1 | AE23: Sp2 | AF23: Sp3 | AG23: Sp4 | AH23: T123 | AI23: T124 | AJ23: T134 | AK23: T234 | AL23: Rk1 | AM23: Rk2 | AN23: Rk3 | AO23: Rk4 | AP23: T1234 | AQ23: T123 | AR23: T124 | AS23: T134 | AT23: T234 | AU23: T12 | AV23: T13 | AW23: T14 | AX23: T23 | AY23: T24 | AZ23: T34 | BA23: NoT | BB23: sRk1 | BC23: sRk2 | BD23: sRk3 | BE23: sRk4
B24: 46186.792 | C24: Boston | D24: =+Instructions!F27 -> Haiti (HAI) | E24: 0 | F24: =+Instructions!F28 -> Scotland (SCO) | G24: 2 | J24: =Q24 -> 1 | K24: {=INDEX(U24:U27,MATCH(S24,$T24:$T27,0))} -> BRA | L24: {=INDEX(V24:V27,MATCH(S24,$T24:$T27,0))} -> 9 | M24: {=INDEX(W24:W27,MATCH(S24,$T24:$T27,0))} -> 7 | N24: {=INDEX(X24:X27,MATCH(S24,$T24:$T27,0))} -> 0 | O24: {=INDEX(Y24:Y27,MATCH(S24,$T24:$T27,0))} -> 7 | Q24: 1 | R24: =ROUND(S24,0) -> 1 | S24: =+SMALL(T24:T27,1) -> 0.95 | T24: =SUM(AL24:AO24)+2.45 -> 0.95 | U24: =+Instructions!E25 -> BRA | V24: =SUM(Z24:AC24) -> 9 | W24: =E23+E25+G27 -> 7 | X24: =G23+G25+E27 -> 0 | Y24: =W24-X24 -> 7 | Z24: x | AA24: =IF(ISBLANK(E23),0,IF(E23>G23,3,IF(E23=G23,1,0))) -> 3 | AB24: =IF(ISBLANK(E25),0,IF(E25>G25,3,IF(E25=G25,1,0))) -> 3 | AC24: =IF(ISBLANK(G27),0,IF(G27>E27,3,IF(G27=E27,1,0))) -> 3 | AD24: x | AE24: =(10*(Y24-Y25)+W24-W25>0) -> TRUE | AF24: =10*(Y24-Y26)+W24-W26>0 -> TRUE | AG24: =10*(Y24-Y27)+W24-W27>0 -> TRUE | AH24: =10000*(AA24+AB24)+(E25-G25+E23-G23)*100+(E25+E23) -> 60606 | AI24: =10000*(AA24+AC24)+(E23-G23+G27-E27)*100+(E23+G27) -> 60202 | AJ24: =10000*(AB24+AC24)+(G27-E27+E25-G25)*100+(G27+E25) -> 60606 | AK24: x | AL24: x | AM24: =IF($V24>$V25,-0.5,IF($V25>$V24,0.5,IF(AE24,-0.5,IF(AD25,0.5,BC24)))) -> -0.5 | AN24: =IF($V24>$V26,-0.5,IF($V26>$V24,0.5,IF(AF24,-0.5,IF(AD26,0.5,BD24)))) -> -0.5 | AO24: =IF($V24>$V27,-0.5,IF($V27>$V24,0.5,IF(AG24,-0.5,IF(AD27,0.5,BE24)))) -> -0.5 | AP24: =AND(AND(V24=V25,V25=V26,V26=V27),AND(W24=W25,W25=W26,W26=W27),AND(X24=X25,X25=X26,X26=X27)) -> FALSE | AQ24: =AND(NOT(AP24),V24=V25,V24=V26,W24=W25,W24=W26,X24=X25,X24=X26) -> FALSE | AR24: =AND(NOT(AP24),V24=V25,V24=V27,W24=W25,W24=W27,X24=X25,X24=X27) -> FALSE | AS24: =AND(NOT(AP24),V24=V26,V24=V27,W24=W26,W24=W27,X24=X26,X24=X27) -> FALSE | AT24: =AND(NOT(AP24),V25=V26,V25=V27,W25=W26,W25=W27,X25=X26,X25=X27) -> FALSE | AU24: =AND(NOT(AP24),NOT(AQ24),NOT(AR24),V24=V25,W24=W25,X24=X25) -> FALSE | AV24: =AND(NOT(AP24),NOT(AQ24),NOT(AS24),V24=V26,W24=W26,X24=X26) -> FALSE | AW24: =AND(NOT(AP24),NOT(AR24),NOT(AS24),V24=V27,W24=W27,X24=X27) -> FALSE | AX24: =AND(NOT(AP24),NOT(AQ24),NOT(AT24),V25=V26,W25=W26) -> FALSE | AY24: =AND(NOT(AP24),NOT(AR24),NOT(AT24),V25=V27,W25=W27,X25=X27) -> FALSE | AZ24: =AND(NOT(AP24),NOT(AS24),NOT(AT24),V26=V27,W26=W27,X26=X27) -> FALSE | BA24: {=AND(NOT(AP24:AZ24))} -> TRUE | BB24: x | BC24: =IF($AU24,IF(G23-E23<0,-0.5,IF(E23-G23<0,0.5,0)),IF($AQ24,IF($AH24>$AH25,-0.5,IF($AH24<$AH25,0.5,0)),IF($AR24,IF($AI24>$AI25,-0.5, IF($AI24<$AI25,0.5,0)),0))) -> 0 | BD24: =IF($AV24,IF(G25-E25<0,-0.5,IF(E25-G25<0,0.5,0)),IF($AQ24,IF($AH24>$AH26,-0.5,IF($AH24<$AH26,0.5,0)),IF($AS24,IF($AJ24>$AJ26,-0.5,IF($AJ24<$AJ26,0.5,0)),0))) -> 0 | BE24: =IF($AW24,IF(E27-G27<0,-0.5,IF(G27-E27<0,0.5,0)),IF($AR24,IF($AI24>$AI27,-0.5,IF($AI24<$AI27,0.5,0)),IF($AS24,IF($AJ24>$AJ27,-0.5, IF($AJ24<$AJ27,0.5,0)),0))) -> 0
B25: 46192.771 | C25: Philadelphia | D25: =+Instructions!F25 -> Brazil (BRA) | E25: 5 | F25: =+Instructions!F27 -> Haiti (HAI) | G25: 0 | J25: =Q25 -> 2 | K25: {=INDEX(U24:U27,MATCH(S25,$T24:$T27,0))} -> MAR | L25: {=INDEX(V24:V27,MATCH(S25,$T24:$T27,0))} -> 6 | M25: {=INDEX(W24:W27,MATCH(S25,$T24:$T27,0))} -> 4 | N25: {=INDEX(X24:X27,MATCH(S25,$T24:$T27,0))} -> 1 | O25: {=INDEX(Y24:Y27,MATCH(S25,$T24:$T27,0))} -> 3 | Q25: =IF(ROUND(S25,0)=ROUND(S24,0),Q24,2) -> 2 | R25: =ROUND(S25,0) -> 2 | S25: =+SMALL(T24:T27,2) -> 1.96 | T25: =SUM(AL25:AO25)+2.46 -> 1.96 | U25: =+Instructions!E26 -> MAR | V25: =SUM(Z25:AC25) -> 6 | W25: =G23+G26+E28 -> 4 | X25: =E23+E26+G28 -> 1 | Y25: =W25-X25 -> 3 | Z25: =IF(ISBLANK(G23),0,IF(AA24=3,0,IF(AA24=1,1,3))) -> 0 | AA25: x | AB25: =IF(ISBLANK(E28),0,IF(AA26=3,0,IF(AA26=1,1,3))) -> 3 | AC25: =IF(ISBLANK(G26),0,IF(G26>E26,3,IF(G26=E26,1,0))) -> 3 | AD25: =(10*(Y24-Y25)+W24-W25<0) -> FALSE | AE25: x | AF25: =10*(Y25-Y26)+W25-W26>0 -> TRUE | AG25: =10*(Y25-Y27)+W25-W27>0 -> TRUE | AH25: =10000*(Z25+AB25)+(G23-E23+E28-G28)*100+(G23+E28) -> 30203 | AI25: =10000*(Z25+AC25)+(G23-E23+G26-E26)*100+(G23+G26) -> 30001 | AJ25: x | AK25: =10000*(AB25+AC25)+(G26-E26+E28-G28)*100+(G26+E28) -> 60404 | AL25: =-AM24 -> 0.5 | AM25: x | AN25: =IF($V25>$V26,-0.5,IF($V26>$V25,0.5,IF(AF25,-0.5,IF(AE26,0.5,BD25)))) -> -0.5 | AO25: =IF($V25>$V27,-0.5,IF($V27>$V25,0.5,IF(AG25,-0.5,IF(AE27,0.5,BE25)))) -> -0.5 | BC25: x | BD25: =IF($AX24,IF(G28-E28<0,-0.5,IF(E28-G28<0,0.5,0)),IF($AQ24,IF($AH25>$AH26,-0.5,IF($AH25<$AH26,0.5,0)),IF($AT24,IF($AK25>$AK26,-0.5,IF($AK25<$AK26,0.5,0)),0))) -> 0 | BE25: =IF($AY24,IF(E26-G26<0,-0.5,IF(G26-E26<0,0.5,0)),IF($AR24,IF($AI25>$AI27,-0.5,IF($AI25<$AI27,0.5,0)),IF($AT24,IF($AK25>$AK27,-0.5,IF($AK25<$AK27,0.5,0)),0))) -> 0
B26: 46192.667 | C26: Boston | D26: =+Instructions!F28 -> Scotland (SCO) | E26: 0 | F26: =+Instructions!F26 -> Morocco (MAR) | G26: 1 | J26: =Q26 -> 3 | K26: {=INDEX(U24:U27,MATCH(S26,$T24:$T27,0))} -> SCO | L26: {=INDEX(V24:V27,MATCH(S26,$T24:$T27,0))} -> 3 | M26: {=INDEX(W24:W27,MATCH(S26,$T24:$T27,0))} -> 2 | N26: {=INDEX(X24:X27,MATCH(S26,$T24:$T27,0))} -> 2 | O26: {=INDEX(Y24:Y27,MATCH(S26,$T24:$T27,0))} -> 0 | Q26: =IF(ROUND(S26,0)=ROUND(S25,0),Q25,3) -> 3 | R26: =ROUND(S26,0) -> 3 | S26: =+SMALL(T24:T27,3) -> 2.98 | T26: =SUM(AL26:AO26)+2.47 -> 3.97 | U26: =+Instructions!E27 -> HAI | V26: =SUM(Z26:AC26) -> 0 | W26: =E24+G25+G28 -> 0 | X26: =G24+E25+E28 -> 10 | Y26: =W26-X26 -> -10 | Z26: =IF(ISBLANK(G25),0,IF(AB24=3,0,IF(AB24=1,1,3))) -> 0 | AA26: =IF(ISBLANK(G28),0,IF(G28>E28,3,IF(G28=E28,1,0))) -> 0 | AB26: x | AC26: =IF(ISBLANK(E24),0,IF(E24>G24,3,IF(E24=G24,1,0))) -> 0 | AD26: =10*(Y24-Y26)+W24-W26<0 -> FALSE | AE26: =10*(Y25-Y26)+W25-W26<0 -> FALSE | AF26: x | AG26: =10*(Y26-Y27)+W26-W27>0 -> FALSE | AH26: =10000*(Z26+AA26)+(G25-E25+G28-E28)*100+(G25+G28) -> -800 | AI26: x | AJ26: =10000*(Z26+AC26)+(E24-G24+G25-E25)*100+(E24+G25) -> -700 | AK26: =10000*(AA26+AC26)+(E24-G24+G28-E28)*100+(E24+G28) -> -500 | AL26: =-AN24 -> 0.5 | AM26: =-AN25 -> 0.5 | AN26: x | AO26: =IF($V26>$V27,-0.5,IF($V27>$V26,0.5,IF(AG26,-0.5,IF(AF27,0.5,BE26)))) -> 0.5 | BD26: x | BE26: =IF($AZ24,IF(G24-E24<0,-0.5,IF(E24-G24<0,0.5,0)),IF($AS24,IF($AJ26>$AJ27,-0.5,IF($AJ26<$AJ27,0.5,0)),IF($AT24,IF($AK26>$AK27,-0.5,IF($AK26<$AK27,0.5,0)),0))) -> 0
B27: 46197.667 | C27: Miami | D27: =+Instructions!F28 -> Scotland (SCO) | E27: 0 | F27: =+Instructions!F25 -> Brazil (BRA) | G27: 1 | J27: =Q27 -> 4 | K27: {=INDEX(U24:U27,MATCH(S27,$T24:$T27,0))} -> HAI | L27: {=INDEX(V24:V27,MATCH(S27,$T24:$T27,0))} -> 0 | M27: {=INDEX(W24:W27,MATCH(S27,$T24:$T27,0))} -> 0 | N27: {=INDEX(X24:X27,MATCH(S27,$T24:$T27,0))} -> 10 | O27: {=INDEX(Y24:Y27,MATCH(S27,$T24:$T27,0))} -> -10 | Q27: =IF(ROUND(S27,0)=ROUND(S26,0),Q26,4) -> 4 | R27: =ROUND(S27,0) -> 4 | S27: =+SMALL(T24:T27,4) -> 3.97 | T27: =SUM(AL27:AO27)+2.48 -> 2.98 | U27: =+Instructions!E28 -> SCO | V27: =SUM(Z27:AC27) -> 3 | W27: =G24+E26+E27 -> 2 | X27: =E24+G26+G27 -> 2 | Y27: =W27-X27 -> 0 | Z27: =IF(ISBLANK(E27),0,IF(AC24=3,0,IF(AC24=1,1,3))) -> 0 | AA27: =IF(ISBLANK(E26),0,IF(AC25=3,0,IF(AC25=1,1,3))) -> 0 | AB27: =IF(ISBLANK(G24),0,IF(AC26=3,0,IF(AC26=1,1,3))) -> 3 | AC27: x | AD27: =10*(Y24-Y27)+W24-W27<0 -> FALSE | AE27: =10*(Y25-Y27)+W25-W27<0 -> FALSE | AF27: =10*(Y26-Y27)+W26-W27<0 -> TRUE | AG27: x | AH27: x | AI27: =10000*(Z27+AA27)+(E26-G26+E27-G27)*100+(E26+E27) -> -200 | AJ27: =10000*(Z27+AB27)+(E27-G27+G24-E24)*100+(E27+G24) -> 30102 | AK27: =10000*(AA27+AB27)+(E26-G26+G24-E24)*100+(E26+G24) -> 30102 | AL27: =-AO24 -> 0.5 | AM27: =-AO25 -> 0.5 | AN27: =-AO26 -> -0.5 | AO27: x | BE27: x
B28: 46197.667 | C28: Atlanta | D28: =+Instructions!F26 -> Morocco (MAR) | E28: 3 | F28: =+Instructions!F27 -> Haiti (HAI) | G28: 0 | K28: =IF(ISBLANK(G28)," ",+IF(OR(J26<3,J25<2),"TIE BREAK! Pick your qualifiers on the Knock-Out Predictions sheet"," "))
B30: Group D
B31: 46185.792 | C31: Los Angeles | D31: =+Instructions!F31 -> USA | E31: 1 | F31: =+Instructions!F32 -> Paraguay (PAR) | G31: 0 | K31: Group D | L31: Pts | M31: GF | N31: GA | O31: GD | T31: Rank | U31: Team | V31: Pts | W31: GF | X31: GC | Y31: DG | Z31: Ag1 | AA31: Ag2 | AB31: Ag3 | AC31: Ag4 | AD31: Sp1 | AE31: Sp2 | AF31: Sp3 | AG31: Sp4 | AH31: T123 | AI31: T124 | AJ31: T134 | AK31: T234 | AL31: Rk1 | AM31: Rk2 | AN31: Rk3 | AO31: Rk4 | AP31: T1234 | AQ31: T123 | AR31: T124 | AS31: T134 | AT31: T234 | AU31: T12 | AV31: T13 | AW31: T14 | AX31: T23 | AY31: T24 | AZ31: T34 | BA31: NoT | BB31: sRk1 | BC31: sRk2 | BD31: sRk3 | BE31: sRk4
B32: 46186.917 | C32: Vancouver | D32: =+Instructions!F33 -> Australia (AUS) | E32: 0 | F32: =+Instructions!F34 -> Türkiye (TUR) | G32: 1 | J32: =Q32 -> 1 | K32: {=INDEX(U32:U35,MATCH(S32,$T32:$T35,0))} -> USA | L32: {=INDEX(V32:V35,MATCH(S32,$T32:$T35,0))} -> 9 | M32: {=INDEX(W32:W35,MATCH(S32,$T32:$T35,0))} -> 3 | N32: {=INDEX(X32:X35,MATCH(S32,$T32:$T35,0))} -> 0 | O32: {=INDEX(Y32:Y35,MATCH(S32,$T32:$T35,0))} -> 3 | Q32: 1 | R32: =ROUND(S32,0) -> 1 | S32: =+SMALL(T32:T35,1) -> 0.95 | T32: =SUM(AL32:AO32)+2.45 -> 0.95 | U32: =+Instructions!E31 -> USA | V32: =SUM(Z32:AC32) -> 9 | W32: =E31+E33+G35 -> 3 | X32: =G31+G33+E35 -> 0 | Y32: =W32-X32 -> 3 | Z32: x | AA32: =IF(ISBLANK(E31),0,IF(E31>G31,3,IF(E31=G31,1,0))) -> 3 | AB32: =IF(ISBLANK(E33),0,IF(E33>G33,3,IF(E33=G33,1,0))) -> 3 | AC32: =IF(ISBLANK(G35),0,IF(G35>E35,3,IF(G35=E35,1,0))) -> 3 | AD32: x | AE32: =(10*(Y32-Y33)+W32-W33>0) -> TRUE | AF32: =10*(Y32-Y34)+W32-W34>0 -> TRUE | AG32: =10*(Y32-Y35)+W32-W35>0 -> TRUE | AH32: =10000*(AA32+AB32)+(E33-G33+E31-G31)*100+(E33+E31) -> 60202 | AI32: =10000*(AA32+AC32)+(E31-G31+G35-E35)*100+(E31+G35) -> 60202 | AJ32: =10000*(AB32+AC32)+(G35-E35+E33-G33)*100+(G35+E33) -> 60202 | AK32: x | AL32: x | AM32: =IF($V32>$V33,-0.5,IF($V33>$V32,0.5,IF(AE32,-0.5,IF(AD33,0.5,BC32)))) -> -0.5 | AN32: =IF($V32>$V34,-0.5,IF($V34>$V32,0.5,IF(AF32,-0.5,IF(AD34,0.5,BD32)))) -> -0.5 | AO32: =IF($V32>$V35,-0.5,IF($V35>$V32,0.5,IF(AG32,-0.5,IF(AD35,0.5,BE32)))) -> -0.5 | AP32: =AND(AND(V32=V33,V33=V34,V34=V35),AND(W32=W33,W33=W34,W34=W35),AND(X32=X33,X33=X34,X34=X35)) -> FALSE | AQ32: =AND(NOT(AP32),V32=V33,V32=V34,W32=W33,W32=W34,X32=X33,X32=X34) -> FALSE | AR32: =AND(NOT(AP32),V32=V33,V32=V35,W32=W33,W32=W35,X32=X33,X32=X35) -> FALSE | AS32: =AND(NOT(AP32),V32=V34,V32=V35,W32=W34,W32=W35,X32=X34,X32=X35) -> FALSE | AT32: =AND(NOT(AP32),V33=V34,V33=V35,W33=W34,W33=W35,X33=X34,X33=X35) -> FALSE | AU32: =AND(NOT(AP32),NOT(AQ32),NOT(AR32),V32=V33,W32=W33,X32=X33) -> FALSE | AV32: =AND(NOT(AP32),NOT(AQ32),NOT(AS32),V32=V34,W32=W34,X32=X34) -> FALSE | AW32: =AND(NOT(AP32),NOT(AR32),NOT(AS32),V32=V35,W32=W35,X32=X35) -> FALSE | AX32: =AND(NOT(AP32),NOT(AQ32),NOT(AT32),V33=V34,W33=W34) -> FALSE | AY32: =AND(NOT(AP32),NOT(AR32),NOT(AT32),V33=V35,W33=W35,X33=X35) -> FALSE | AZ32: =AND(NOT(AP32),NOT(AS32),NOT(AT32),V34=V35,W34=W35,X34=X35) -> FALSE | BA32: {=AND(NOT(AP32:AZ32))} -> TRUE | BB32: x | BC32: =IF($AU32,IF(G31-E31<0,-0.5,IF(E31-G31<0,0.5,0)),IF($AQ32,IF($AH32>$AH33,-0.5,IF($AH32<$AH33,0.5,0)),IF($AR32,IF($AI32>$AI33,-0.5, IF($AI32<$AI33,0.5,0)),0))) -> 0 | BD32: =IF($AV32,IF(G33-E33<0,-0.5,IF(E33-G33<0,0.5,0)),IF($AQ32,IF($AH32>$AH34,-0.5,IF($AH32<$AH34,0.5,0)),IF($AS32,IF($AJ32>$AJ34,-0.5,IF($AJ32<$AJ34,0.5,0)),0))) -> 0 | BE32: =IF($AW32,IF(E35-G35<0,-0.5,IF(G35-E35<0,0.5,0)),IF($AR32,IF($AI32>$AI35,-0.5,IF($AI32<$AI35,0.5,0)),IF($AS32,IF($AJ32>$AJ35,-0.5, IF($AJ32<$AJ35,0.5,0)),0))) -> 0
B33: 46192.542 | C33: Seattle | D33: =+Instructions!F31 -> USA | E33: 1 | F33: =+Instructions!F33 -> Australia (AUS) | G33: 0 | J33: =Q33 -> 2 | K33: {=INDEX(U32:U35,MATCH(S33,$T32:$T35,0))} -> TUR | L33: {=INDEX(V32:V35,MATCH(S33,$T32:$T35,0))} -> 4 | M33: {=INDEX(W32:W35,MATCH(S33,$T32:$T35,0))} -> 1 | N33: {=INDEX(X32:X35,MATCH(S33,$T32:$T35,0))} -> 1 | O33: {=INDEX(Y32:Y35,MATCH(S33,$T32:$T35,0))} -> 0 | Q33: =IF(ROUND(S33,0)=ROUND(S32,0),Q32,2) -> 2 | R33: =ROUND(S33,0) -> 2 | S33: =+SMALL(T32:T35,2) -> 1.98 | T33: =SUM(AL33:AO33)+2.46 -> 2.96 | U33: =+Instructions!E32 -> PAR | V33: =SUM(Z33:AC33) -> 2 | W33: =G31+G34+E36 -> 0 | X33: =E31+E34+G36 -> 1 | Y33: =W33-X33 -> -1 | Z33: =IF(ISBLANK(G31),0,IF(AA32=3,0,IF(AA32=1,1,3))) -> 0 | AA33: x | AB33: =IF(ISBLANK(E36),0,IF(AA34=3,0,IF(AA34=1,1,3))) -> 1 | AC33: =IF(ISBLANK(G34),0,IF(G34>E34,3,IF(G34=E34,1,0))) -> 1 | AD33: =(10*(Y32-Y33)+W32-W33<0) -> FALSE | AE33: x | AF33: =10*(Y33-Y34)+W33-W34>0 -> TRUE | AG33: =10*(Y33-Y35)+W33-W35>0 -> FALSE | AH33: =10000*(Z33+AB33)+(G31-E31+E36-G36)*100+(G31+E36) -> 9900 | AI33: =10000*(Z33+AC33)+(G31-E31+G34-E34)*100+(G31+G34) -> 9900 | AJ33: x | AK33: =10000*(AB33+AC33)+(G34-E34+E36-G36)*100+(G34+E36) -> 20000 | AL33: =-AM32 -> 0.5 | AM33: x | AN33: =IF($V33>$V34,-0.5,IF($V34>$V33,0.5,IF(AF33,-0.5,IF(AE34,0.5,BD33)))) -> -0.5 | AO33: =IF($V33>$V35,-0.5,IF($V35>$V33,0.5,IF(AG33,-0.5,IF(AE35,0.5,BE33)))) -> 0.5 | BC33: x | BD33: =IF($AX32,IF(G36-E36<0,-0.5,IF(E36-G36<0,0.5,0)),IF($AQ32,IF($AH33>$AH34,-0.5,IF($AH33<$AH34,0.5,0)),IF($AT32,IF($AK33>$AK34,-0.5,IF($AK33<$AK34,0.5,0)),0))) -> 0 | BE33: =IF($AY32,IF(E34-G34<0,-0.5,IF(G34-E34<0,0.5,0)),IF($AR32,IF($AI33>$AI35,-0.5,IF($AI33<$AI35,0.5,0)),IF($AT32,IF($AK33>$AK35,-0.5,IF($AK33<$AK35,0.5,0)),0))) -> 0
B34: 46192.875 | C34: San Francisco | D34: =+Instructions!F34 -> Türkiye (TUR) | E34: 0 | F34: =+Instructions!F32 -> Paraguay (PAR) | G34: 0 | J34: =Q34 -> 3 | K34: {=INDEX(U32:U35,MATCH(S34,$T32:$T35,0))} -> PAR | L34: {=INDEX(V32:V35,MATCH(S34,$T32:$T35,0))} -> 2 | M34: {=INDEX(W32:W35,MATCH(S34,$T32:$T35,0))} -> 0 | N34: {=INDEX(X32:X35,MATCH(S34,$T32:$T35,0))} -> 1 | O34: {=INDEX(Y32:Y35,MATCH(S34,$T32:$T35,0))} -> -1 | Q34: =IF(ROUND(S34,0)=ROUND(S33,0),Q33,3) -> 3 | R34: =ROUND(S34,0) -> 3 | S34: =+SMALL(T32:T35,3) -> 2.96 | T34: =SUM(AL34:AO34)+2.47 -> 3.97 | U34: =+Instructions!E33 -> AUS | V34: =SUM(Z34:AC34) -> 1 | W34: =E32+G33+G36 -> 0 | X34: =G32+E33+E36 -> 2 | Y34: =W34-X34 -> -2 | Z34: =IF(ISBLANK(G33),0,IF(AB32=3,0,IF(AB32=1,1,3))) -> 0 | AA34: =IF(ISBLANK(G36),0,IF(G36>E36,3,IF(G36=E36,1,0))) -> 1 | AB34: x | AC34: =IF(ISBLANK(E32),0,IF(E32>G32,3,IF(E32=G32,1,0))) -> 0 | AD34: =10*(Y32-Y34)+W32-W34<0 -> FALSE | AE34: =10*(Y33-Y34)+W33-W34<0 -> FALSE | AF34: x | AG34: =10*(Y34-Y35)+W34-W35>0 -> FALSE | AH34: =10000*(Z34+AA34)+(G33-E33+G36-E36)*100+(G33+G36) -> 9900 | AI34: x | AJ34: =10000*(Z34+AC34)+(E32-G32+G33-E33)*100+(E32+G33) -> -200 | AK34: =10000*(AA34+AC34)+(E32-G32+G36-E36)*100+(E32+G36) -> 9900 | AL34: =-AN32 -> 0.5 | AM34: =-AN33 -> 0.5 | AN34: x | AO34: =IF($V34>$V35,-0.5,IF($V35>$V34,0.5,IF(AG34,-0.5,IF(AF35,0.5,BE34)))) -> 0.5 | BD34: x | BE34: =IF($AZ32,IF(G32-E32<0,-0.5,IF(E32-G32<0,0.5,0)),IF($AS32,IF($AJ34>$AJ35,-0.5,IF($AJ34<$AJ35,0.5,0)),IF($AT32,IF($AK34>$AK35,-0.5,IF($AK34<$AK35,0.5,0)),0))) -> 0
B35: 46198.833 | C35: Los Angeles | D35: =+Instructions!F34 -> Türkiye (TUR) | E35: 0 | F35: =+Instructions!F31 -> USA | G35: 1 | J35: =Q35 -> 4 | K35: {=INDEX(U32:U35,MATCH(S35,$T32:$T35,0))} -> AUS | L35: {=INDEX(V32:V35,MATCH(S35,$T32:$T35,0))} -> 1 | M35: {=INDEX(W32:W35,MATCH(S35,$T32:$T35,0))} -> 0 | N35: {=INDEX(X32:X35,MATCH(S35,$T32:$T35,0))} -> 2 | O35: {=INDEX(Y32:Y35,MATCH(S35,$T32:$T35,0))} -> -2 | Q35: =IF(ROUND(S35,0)=ROUND(S34,0),Q34,4) -> 4 | R35: =ROUND(S35,0) -> 4 | S35: =+SMALL(T32:T35,4) -> 3.97 | T35: =SUM(AL35:AO35)+2.48 -> 1.98 | U35: =+Instructions!E34 -> TUR | V35: =SUM(Z35:AC35) -> 4 | W35: =G32+E34+E35 -> 1 | X35: =E32+G34+G35 -> 1 | Y35: =W35-X35 -> 0 | Z35: =IF(ISBLANK(E35),0,IF(AC32=3,0,IF(AC32=1,1,3))) -> 0 | AA35: =IF(ISBLANK(E34),0,IF(AC33=3,0,IF(AC33=1,1,3))) -> 1 | AB35: =IF(ISBLANK(G32),0,IF(AC34=3,0,IF(AC34=1,1,3))) -> 3 | AC35: x | AD35: =10*(Y32-Y35)+W32-W35<0 -> FALSE | AE35: =10*(Y33-Y35)+W33-W35<0 -> TRUE | AF35: =10*(Y34-Y35)+W34-W35<0 -> TRUE | AG35: x | AH35: x | AI35: =10000*(Z35+AA35)+(E34-G34+E35-G35)*100+(E34+E35) -> 9900 | AJ35: =10000*(Z35+AB35)+(E35-G35+G32-E32)*100+(E35+G32) -> 30001 | AK35: =10000*(AA35+AB35)+(E34-G34+G32-E32)*100+(E34+G32) -> 40101 | AL35: =-AO32 -> 0.5 | AM35: =-AO33 -> -0.5 | AN35: =-AO34 -> -0.5 | AO35: x | BE35: x
B36: 46198.833 | C36: San Francisco | D36: =+Instructions!F32 -> Paraguay (PAR) | E36: 0 | F36: =+Instructions!F33 -> Australia (AUS) | G36: 0 | K36: =IF(ISBLANK(G36)," ",+IF(OR(J34<3,J33<2),"TIE BREAK! Pick your qualifiers on the Knock-Out Predictions sheet"," "))
B38: Group E
B39: 46187.458 | C39: Houston | D39: =+Instructions!F37 -> Germany (GER) | E39: 5 | F39: =+Instructions!F38 -> Curaçao (CUW) | G39: 0 | K39: Group E | L39: Pts | M39: GF | N39: GA | O39: GD | T39: Rank | U39: Team | V39: Pts | W39: GF | X39: GC | Y39: DG | Z39: Ag1 | AA39: Ag2 | AB39: Ag3 | AC39: Ag4 | AD39: Sp1 | AE39: Sp2 | AF39: Sp3 | AG39: Sp4 | AH39: T123 | AI39: T124 | AJ39: T134 | AK39: T234 | AL39: Rk1 | AM39: Rk2 | AN39: Rk3 | AO39: Rk4 | AP39: T1234 | AQ39: T123 | AR39: T124 | AS39: T134 | AT39: T234 | AU39: T12 | AV39: T13 | AW39: T14 | AX39: T23 | AY39: T24 | AZ39: T34 | BA39: NoT | BB39: sRk1 | BC39: sRk2 | BD39: sRk3 | BE39: sRk4
B40: 46187.792 | C40: Philadelphia | D40: =+Instructions!F39 -> Côte d'Ivoire (CIV) | E40: 0 | F40: =+Instructions!F40 -> Ecuador (ECU) | G40: 1 | J40: =Q40 -> 1 | K40: {=INDEX(U40:U43,MATCH(S40,$T40:$T43,0))} -> GER | L40: {=INDEX(V40:V43,MATCH(S40,$T40:$T43,0))} -> 9 | M40: {=INDEX(W40:W43,MATCH(S40,$T40:$T43,0))} -> 8 | N40: {=INDEX(X40:X43,MATCH(S40,$T40:$T43,0))} -> 0 | O40: {=INDEX(Y40:Y43,MATCH(S40,$T40:$T43,0))} -> 8 | Q40: 1 | R40: =ROUND(S40,0) -> 1 | S40: =+SMALL(T40:T43,1) -> 0.95 | T40: =SUM(AL40:AO40)+2.45 -> 0.95 | U40: =+Instructions!E37 -> GER | V40: =SUM(Z40:AC40) -> 9 | W40: =E39+E41+G43 -> 8 | X40: =G39+G41+E43 -> 0 | Y40: =W40-X40 -> 8 | Z40: x | AA40: =IF(ISBLANK(E39),0,IF(E39>G39,3,IF(E39=G39,1,0))) -> 3 | AB40: =IF(ISBLANK(E41),0,IF(E41>G41,3,IF(E41=G41,1,0))) -> 3 | AC40: =IF(ISBLANK(G43),0,IF(G43>E43,3,IF(G43=E43,1,0))) -> 3 | AD40: x | AE40: =(10*(Y40-Y41)+W40-W41>0) -> TRUE | AF40: =10*(Y40-Y42)+W40-W42>0 -> TRUE | AG40: =10*(Y40-Y43)+W40-W43>0 -> TRUE | AH40: =10000*(AA40+AB40)+(E41-G41+E39-G39)*100+(E41+E39) -> 60707 | AI40: =10000*(AA40+AC40)+(E39-G39+G43-E43)*100+(E39+G43) -> 60606 | AJ40: =10000*(AB40+AC40)+(G43-E43+E41-G41)*100+(G43+E41) -> 60303 | AK40: x | AL40: x | AM40: =IF($V40>$V41,-0.5,IF($V41>$V40,0.5,IF(AE40,-0.5,IF(AD41,0.5,BC40)))) -> -0.5 | AN40: =IF($V40>$V42,-0.5,IF($V42>$V40,0.5,IF(AF40,-0.5,IF(AD42,0.5,BD40)))) -> -0.5 | AO40: =IF($V40>$V43,-0.5,IF($V43>$V40,0.5,IF(AG40,-0.5,IF(AD43,0.5,BE40)))) -> -0.5 | AP40: =AND(AND(V40=V41,V41=V42,V42=V43),AND(W40=W41,W41=W42,W42=W43),AND(X40=X41,X41=X42,X42=X43)) -> FALSE | AQ40: =AND(NOT(AP40),V40=V41,V40=V42,W40=W41,W40=W42,X40=X41,X40=X42) -> FALSE | AR40: =AND(NOT(AP40),V40=V41,V40=V43,W40=W41,W40=W43,X40=X41,X40=X43) -> FALSE | AS40: =AND(NOT(AP40),V40=V42,V40=V43,W40=W42,W40=W43,X40=X42,X40=X43) -> FALSE | AT40: =AND(NOT(AP40),V41=V42,V41=V43,W41=W42,W41=W43,X41=X42,X41=X43) -> FALSE | AU40: =AND(NOT(AP40),NOT(AQ40),NOT(AR40),V40=V41,W40=W41,X40=X41) -> FALSE | AV40: =AND(NOT(AP40),NOT(AQ40),NOT(AS40),V40=V42,W40=W42,X40=X42) -> FALSE | AW40: =AND(NOT(AP40),NOT(AR40),NOT(AS40),V40=V43,W40=W43,X40=X43) -> FALSE | AX40: =AND(NOT(AP40),NOT(AQ40),NOT(AT40),V41=V42,W41=W42) -> FALSE | AY40: =AND(NOT(AP40),NOT(AR40),NOT(AT40),V41=V43,W41=W43,X41=X43) -> FALSE | AZ40: =AND(NOT(AP40),NOT(AS40),NOT(AT40),V42=V43,W42=W43,X42=X43) -> FALSE | BA40: {=AND(NOT(AP40:AZ40))} -> TRUE | BB40: x | BC40: =IF($AU40,IF(G39-E39<0,-0.5,IF(E39-G39<0,0.5,0)),IF($AQ40,IF($AH40>$AH41,-0.5,IF($AH40<$AH41,0.5,0)),IF($AR40,IF($AI40>$AI41,-0.5, IF($AI40<$AI41,0.5,0)),0))) -> 0 | BD40: =IF($AV40,IF(G41-E41<0,-0.5,IF(E41-G41<0,0.5,0)),IF($AQ40,IF($AH40>$AH42,-0.5,IF($AH40<$AH42,0.5,0)),IF($AS40,IF($AJ40>$AJ42,-0.5,IF($AJ40<$AJ42,0.5,0)),0))) -> 0 | BE40: =IF($AW40,IF(E43-G43<0,-0.5,IF(G43-E43<0,0.5,0)),IF($AR40,IF($AI40>$AI43,-0.5,IF($AI40<$AI43,0.5,0)),IF($AS40,IF($AJ40>$AJ43,-0.5, IF($AJ40<$AJ43,0.5,0)),0))) -> 0
B41: 46193.583 | C41: Toronto | D41: =+Instructions!F37 -> Germany (GER) | E41: 2 | F41: =+Instructions!F39 -> Côte d'Ivoire (CIV) | G41: 0 | J41: =Q41 -> 2 | K41: {=INDEX(U40:U43,MATCH(S41,$T40:$T43,0))} -> ECU | L41: {=INDEX(V40:V43,MATCH(S41,$T40:$T43,0))} -> 6 | M41: {=INDEX(W40:W43,MATCH(S41,$T40:$T43,0))} -> 4 | N41: {=INDEX(X40:X43,MATCH(S41,$T40:$T43,0))} -> 1 | O41: {=INDEX(Y40:Y43,MATCH(S41,$T40:$T43,0))} -> 3 | Q41: =IF(ROUND(S41,0)=ROUND(S40,0),Q40,2) -> 2 | R41: =ROUND(S41,0) -> 2 | S41: =+SMALL(T40:T43,2) -> 1.98 | T41: =SUM(AL41:AO41)+2.46 -> 3.96 | U41: =+Instructions!E38 -> CUW | V41: =SUM(Z41:AC41) -> 0 | W41: =G39+G42+E44 -> 0 | X41: =E39+E42+G44 -> 11 | Y41: =W41-X41 -> -11 | Z41: =IF(ISBLANK(G39),0,IF(AA40=3,0,IF(AA40=1,1,3))) -> 0 | AA41: x | AB41: =IF(ISBLANK(E44),0,IF(AA42=3,0,IF(AA42=1,1,3))) -> 0 | AC41: =IF(ISBLANK(G42),0,IF(G42>E42,3,IF(G42=E42,1,0))) -> 0 | AD41: =(10*(Y40-Y41)+W40-W41<0) -> FALSE | AE41: x | AF41: =10*(Y41-Y42)+W41-W42>0 -> FALSE | AG41: =10*(Y41-Y43)+W41-W43>0 -> FALSE | AH41: =10000*(Z41+AB41)+(G39-E39+E44-G44)*100+(G39+E44) -> -800 | AI41: =10000*(Z41+AC41)+(G39-E39+G42-E42)*100+(G39+G42) -> -800 | AJ41: x | AK41: =10000*(AB41+AC41)+(G42-E42+E44-G44)*100+(G42+E44) -> -600 | AL41: =-AM40 -> 0.5 | AM41: x | AN41: =IF($V41>$V42,-0.5,IF($V42>$V41,0.5,IF(AF41,-0.5,IF(AE42,0.5,BD41)))) -> 0.5 | AO41: =IF($V41>$V43,-0.5,IF($V43>$V41,0.5,IF(AG41,-0.5,IF(AE43,0.5,BE41)))) -> 0.5 | BC41: x | BD41: =IF($AX40,IF(G44-E44<0,-0.5,IF(E44-G44<0,0.5,0)),IF($AQ40,IF($AH41>$AH42,-0.5,IF($AH41<$AH42,0.5,0)),IF($AT40,IF($AK41>$AK42,-0.5,IF($AK41<$AK42,0.5,0)),0))) -> 0 | BE41: =IF($AY40,IF(E42-G42<0,-0.5,IF(G42-E42<0,0.5,0)),IF($AR40,IF($AI41>$AI43,-0.5,IF($AI41<$AI43,0.5,0)),IF($AT40,IF($AK41>$AK43,-0.5,IF($AK41<$AK43,0.5,0)),0))) -> 0
B42: 46193.75 | C42: Kansas City | D42: =+Instructions!F40 -> Ecuador (ECU) | E42: 3 | F42: =+Instructions!F38 -> Curaçao (CUW) | G42: 0 | J42: =Q42 -> 3 | K42: {=INDEX(U40:U43,MATCH(S42,$T40:$T43,0))} -> CIV | L42: {=INDEX(V40:V43,MATCH(S42,$T40:$T43,0))} -> 3 | M42: {=INDEX(W40:W43,MATCH(S42,$T40:$T43,0))} -> 3 | N42: {=INDEX(X40:X43,MATCH(S42,$T40:$T43,0))} -> 3 | O42: {=INDEX(Y40:Y43,MATCH(S42,$T40:$T43,0))} -> 0 | Q42: =IF(ROUND(S42,0)=ROUND(S41,0),Q41,3) -> 3 | R42: =ROUND(S42,0) -> 3 | S42: =+SMALL(T40:T43,3) -> 2.97 | T42: =SUM(AL42:AO42)+2.47 -> 2.97 | U42: =+Instructions!E39 -> CIV | V42: =SUM(Z42:AC42) -> 3 | W42: =E40+G41+G44 -> 3 | X42: =G40+E41+E44 -> 3 | Y42: =W42-X42 -> 0 | Z42: =IF(ISBLANK(G41),0,IF(AB40=3,0,IF(AB40=1,1,3))) -> 0 | AA42: =IF(ISBLANK(G44),0,IF(G44>E44,3,IF(G44=E44,1,0))) -> 3 | AB42: x | AC42: =IF(ISBLANK(E40),0,IF(E40>G40,3,IF(E40=G40,1,0))) -> 0 | AD42: =10*(Y40-Y42)+W40-W42<0 -> FALSE | AE42: =10*(Y41-Y42)+W41-W42<0 -> TRUE | AF42: x | AG42: =10*(Y42-Y43)+W42-W43>0 -> FALSE | AH42: =10000*(Z42+AA42)+(G41-E41+G44-E44)*100+(G41+G44) -> 30103 | AI42: x | AJ42: =10000*(Z42+AC42)+(E40-G40+G41-E41)*100+(E40+G41) -> -300 | AK42: =10000*(AA42+AC42)+(E40-G40+G44-E44)*100+(E40+G44) -> 30203 | AL42: =-AN40 -> 0.5 | AM42: =-AN41 -> -0.5 | AN42: x | AO42: =IF($V42>$V43,-0.5,IF($V43>$V42,0.5,IF(AG42,-0.5,IF(AF43,0.5,BE42)))) -> 0.5 | BD42: x | BE42: =IF($AZ40,IF(G40-E40<0,-0.5,IF(E40-G40<0,0.5,0)),IF($AS40,IF($AJ42>$AJ43,-0.5,IF($AJ42<$AJ43,0.5,0)),IF($AT40,IF($AK42>$AK43,-0.5,IF($AK42<$AK43,0.5,0)),0))) -> 0
B43: 46198.583 | C43: New Jersey | D43: =+Instructions!F40 -> Ecuador (ECU) | E43: 0 | F43: =+Instructions!F37 -> Germany (GER) | G43: 1 | J43: =Q43 -> 4 | K43: {=INDEX(U40:U43,MATCH(S43,$T40:$T43,0))} -> CUW | L43: {=INDEX(V40:V43,MATCH(S43,$T40:$T43,0))} -> 0 | M43: {=INDEX(W40:W43,MATCH(S43,$T40:$T43,0))} -> 0 | N43: {=INDEX(X40:X43,MATCH(S43,$T40:$T43,0))} -> 11 | O43: {=INDEX(Y40:Y43,MATCH(S43,$T40:$T43,0))} -> -11 | Q43: =IF(ROUND(S43,0)=ROUND(S42,0),Q42,4) -> 4 | R43: =ROUND(S43,0) -> 4 | S43: =+SMALL(T40:T43,4) -> 3.96 | T43: =SUM(AL43:AO43)+2.48 -> 1.98 | U43: =+Instructions!E40 -> ECU | V43: =SUM(Z43:AC43) -> 6 | W43: =G40+E42+E43 -> 4 | X43: =E40+G42+G43 -> 1 | Y43: =W43-X43 -> 3 | Z43: =IF(ISBLANK(E43),0,IF(AC40=3,0,IF(AC40=1,1,3))) -> 0 | AA43: =IF(ISBLANK(E42),0,IF(AC41=3,0,IF(AC41=1,1,3))) -> 3 | AB43: =IF(ISBLANK(G40),0,IF(AC42=3,0,IF(AC42=1,1,3))) -> 3 | AC43: x | AD43: =10*(Y40-Y43)+W40-W43<0 -> FALSE | AE43: =10*(Y41-Y43)+W41-W43<0 -> TRUE | AF43: =10*(Y42-Y43)+W42-W43<0 -> TRUE | AG43: x | AH43: x | AI43: =10000*(Z43+AA43)+(E42-G42+E43-G43)*100+(E42+E43) -> 30203 | AJ43: =10000*(Z43+AB43)+(E43-G43+G40-E40)*100+(E43+G40) -> 30001 | AK43: =10000*(AA43+AB43)+(E42-G42+G40-E40)*100+(E42+G40) -> 60404 | AL43: =-AO40 -> 0.5 | AM43: =-AO41 -> -0.5 | AN43: =-AO42 -> -0.5 | AO43: x | BE43: x
B44: 46198.583 | C44: Philadelphia | D44: =+Instructions!F38 -> Curaçao (CUW) | E44: 0 | F44: =+Instructions!F39 -> Côte d'Ivoire (CIV) | G44: 3 | K44: =IF(ISBLANK(G44)," ",+IF(OR(J42<3,J41<2),"TIE BREAK! Pick your qualifiers on the Knock-Out Predictions sheet"," "))
B46: Group F
...

Sheet Knock-Out Predictions
B2: Instructions
B3: 1. Enter your name and team name to the right | M3: Entrant name: | N3: Edward Sherrington
B4: 2. Enter the teams you predict to progress from the group stage and through each knock-out round in the grey cells | M4: Team name: | N4: 3 Lions on the Jersey
B5: NOTES: | C5: - PLEASE ONLY USE THE OFFICIAL FIFA THREE-LETTER TEAM CODES SHOWN IN THE INSTRUCTIONS
C6: - The Last 32 below will be auto-completed from your group stage predictions, however you can overwrite these predictions if you wish.
B8: GROUP A
B9: =+'Group Stage Predictions'!B7 -> 46184.542 | C9: =+'Group Stage Predictions'!C7 -> Mexico City | D9: =+'Group Stage Predictions'!D7 -> Mexico (MEX) | E9: =+'Group Stage Predictions'!E7 -> 1 | F9: =+'Group Stage Predictions'!F7 -> South Africa (RSA) | G9: =+'Group Stage Predictions'!G7 -> 0 | J9: =+IF(ISBLANK('Group Stage Predictions'!E7)," ",'Group Stage Predictions'!K9) -> KOR | K9: 2A
B10: =+'Group Stage Predictions'!B8 -> 46184.833 | C10: =+'Group Stage Predictions'!C8 -> Guadalajara | D10: =+'Group Stage Predictions'!D8 -> Korea Republic (KOR) | E10: =+'Group Stage Predictions'!E8 -> 0 | F10: =+'Group Stage Predictions'!F8 -> Czechia (CZE) | G10: =+'Group Stage Predictions'!G8 -> 0 | I10: 43279.542
B11: =+'Group Stage Predictions'!B9 -> 46191.792 | C11: =+'Group Stage Predictions'!C9 -> Guadalajara | D11: =+'Group Stage Predictions'!D9 -> Mexico (MEX) | E11: =+'Group Stage Predictions'!E9 -> 1 | F11: =+'Group Stage Predictions'!F9 -> Korea Republic (KOR) | G11: =+'Group Stage Predictions'!G9 -> 0 | I11: Los Angeles | L11: CAN
B12: =+'Group Stage Predictions'!B10 -> 46191.417 | C12: =+'Group Stage Predictions'!C10 -> Atlanta | D12: =+'Group Stage Predictions'!D10 -> Czechia (CZE) | E12: =+'Group Stage Predictions'!E10 -> 0 | F12: =+'Group Stage Predictions'!F10 -> South Africa (RSA) | G12: =+'Group Stage Predictions'!G10 -> 0
B13: =+'Group Stage Predictions'!B11 -> 46197.792 | C13: =+'Group Stage Predictions'!C11 -> Mexico City | D13: =+'Group Stage Predictions'!D11 -> Czechia (CZE) | E13: =+'Group Stage Predictions'!E11 -> 0 | F13: =+'Group Stage Predictions'!F11 -> Mexico (MEX) | G13: =+'Group Stage Predictions'!G11 -> 1 | J13: =+IF(ISBLANK('Group Stage Predictions'!E15)," ",+'Group Stage Predictions'!K17) -> CAN | K13: 2B
B14: =+'Group Stage Predictions'!B12 -> 46197.792 | C14: =+'Group Stage Predictions'!C12 -> Monterrey | D14: =+'Group Stage Predictions'!D12 -> South Africa (RSA) | E14: =+'Group Stage Predictions'!E12 -> 0 | F14: =+'Group Stage Predictions'!F12 -> Korea Republic (KOR) | G14: =+'Group Stage Predictions'!G12 -> 1 | L14: 43285.458
L15: Houston | M15: NED
B16: GROUP B | J16: =+IF(ISBLANK('Group Stage Predictions'!E47)," ",+'Group Stage Predictions'!K48) -> NED | K16: 1F
B17: =+'Group Stage Predictions'!B15 -> 46185.542 | C17: =+'Group Stage Predictions'!C15 -> Toronto | D17: =+'Group Stage Predictions'!D15 -> Canada (CAN) | E17: =+'Group Stage Predictions'!E15 -> 1 | F17: =+'Group Stage Predictions'!F15 -> Bosnia and Herzegovina (BIH) | G17: =+'Group Stage Predictions'!G15 -> 0 | I17: 43280.792
B18: =+'Group Stage Predictions'!B16 -> 46186.542 | C18: =+'Group Stage Predictions'!C16 -> San Francisco | D18: =+'Group Stage Predictions'!D16 -> Qatar (QAT) | E18: =+'Group Stage Predictions'!E16 -> 0 | F18: =+'Group Stage Predictions'!F16 -> Switzerland (SUI) | G18: =+'Group Stage Predictions'!G16 -> 2 | I18: Monterrey | L18: NED
B19: =+'Group Stage Predictions'!B17 -> 46191.667 | C19: =+'Group Stage Predictions'!C17 -> Vancouver | D19: =+'Group Stage Predictions'!D17 -> Canada (CAN) | E19: =+'Group Stage Predictions'!E17 -> 1 | F19: =+'Group Stage Predictions'!F17 -> Qatar (QAT) | G19: =+'Group Stage Predictions'!G17 -> 0
B20: =+'Group Stage Predictions'!B18 -> 46191.542 | C20: =+'Group Stage Predictions'!C18 -> Los Angeles | D20: =+'Group Stage Predictions'!D18 -> Switzerland (SUI) | E20: =+'Group Stage Predictions'!E18 -> 1 | F20: =+'Group Stage Predictions'!F18 -> Bosnia and Herzegovina (BIH) | G20: =+'Group Stage Predictions'!G18 -> 0 | J20: =+IF(ISBLANK('Group Stage Predictions'!G23)," ",+'Group Stage Predictions'!K25) -> MAR | K20: 2C
B21: =+'Group Stage Predictions'!B19 -> 46197.542 | C21: =+'Group Stage Predictions'!C19 -> Vancouver | D21: =+'Group Stage Predictions'!D19 -> Switzerland (SUI) | E21: =+'Group Stage Predictions'!E19 -> 1 | F21: =+'Group Stage Predictions'!F19 -> Canada (CAN) | G21: =+'Group Stage Predictions'!G19 -> 0
B22: =+'Group Stage Predictions'!B20 -> 46197.542 | C22: =+'Group Stage Predictions'!C20 -> Seattle | D22: =+'Group Stage Predictions'!D20 -> Bosnia and Herzegovina (BIH) | E22: =+'Group Stage Predictions'!E20 -> 1 | F22: =+'Group Stage Predictions'!F20 -> Qatar (QAT) | G22: =+'Group Stage Predictions'!G20 -> 0 | M22: 43290.583
J23: =+IF(ISBLANK('Group Stage Predictions'!E39)," ",+'Group Stage Predictions'!K40) -> GER | K23: 1E | M23: Boston | N23: FRA
B24: GROUP C | I24: 43280.604
B25: =+'Group Stage Predictions'!B23 -> 46186.667 | C25: =+'Group Stage Predictions'!C23 -> New Jersey | D25: =+'Group Stage Predictions'!D23 -> Brazil (BRA) | E25: =+'Group Stage Predictions'!E23 -> 1 | F25: =+'Group Stage Predictions'!F23 -> Morocco (MAR) | G25: =+'Group Stage Predictions'!G23 -> 0 | I25: Boston | L25: GER
B26: =+'Group Stage Predictions'!B24 -> 46186.792 | C26: =+'Group Stage Predictions'!C24 -> Boston | D26: =+'Group Stage Predictions'!D24 -> Haiti (HAI) | E26: =+'Group Stage Predictions'!E24 -> 0 | F26: =+'Group Stage Predictions'!F24 -> Scotland (SCO) | G26: =+'Group Stage Predictions'!G24 -> 2
B27: =+'Group Stage Predictions'!B25 -> 46192.771 | C27: =+'Group Stage Predictions'!C25 -> Philadelphia | D27: =+'Group Stage Predictions'!D25 -> Brazil (BRA) | E27: =+'Group Stage Predictions'!E25 -> 5 | F27: =+'Group Stage Predictions'!F25 -> Haiti (HAI) | G27: =+'Group Stage Predictions'!G25 -> 0 | J27: =+IF(ISBLANK('Group Stage Predictions'!E47)," ",'Group Stage Predictions'!AO121) -> SCO | K27: 3ABCDF
B28: =+'Group Stage Predictions'!B26 -> 46192.667 | C28: =+'Group Stage Predictions'!C26 -> Boston | D28: =+'Group Stage Predictions'!D26 -> Scotland (SCO) | E28: =+'Group Stage Predictions'!E26 -> 0 | F28: =+'Group Stage Predictions'!F26 -> Morocco (MAR) | G28: =+'Group Stage Predictions'!G26 -> 1 | L28: 43285.625
B29: =+'Group Stage Predictions'!B27 -> 46197.667 | C29: =+'Group Stage Predictions'!C27 -> Miami | D29: =+'Group Stage Predictions'!D27 -> Scotland (SCO) | E29: =+'Group Stage Predictions'!E27 -> 0 | F29: =+'Group Stage Predictions'!F27 -> Brazil (BRA) | G29: =+'Group Stage Predictions'!G27 -> 1 | L29: Philadelphia
B30: =+'Group Stage Predictions'!B28 -> 46197.667 | C30: =+'Group Stage Predictions'!C28 -> Atlanta | D30: =+'Group Stage Predictions'!D28 -> Morocco (MAR) | E30: =+'Group Stage Predictions'!E28 -> 3 | F30: =+'Group Stage Predictions'!F28 -> Haiti (HAI) | G30: =+'Group Stage Predictions'!G28 -> 0 | J30: =+IF(ISBLANK('Group Stage Predictions'!E71)," ",'Group Stage Predictions'!K72) -> FRA | K30: 1I | M30: FRA
I31: 43281.625
B32: GROUP D | I32: New Jersey | L32: FRA
B33: =+'Group Stage Predictions'!B31 -> 46185.792 | C33: =+'Group Stage Predictions'!C31 -> Los Angeles | D33: =+'Group Stage Predictions'!D31 -> USA | E33: =+'Group Stage Predictions'!E31 -> 1 | F33: =+'Group Stage Predictions'!F31 -> Paraguay (PAR) | G33: =+'Group Stage Predictions'!G31 -> 0
B34: =+'Group Stage Predictions'!B32 -> 46186.917 | C34: =+'Group Stage Predictions'!C32 -> Vancouver | D34: =+'Group Stage Predictions'!D32 -> Australia (AUS) | E34: =+'Group Stage Predictions'!E32 -> 0 | F34: =+'Group Stage Predictions'!F32 -> Türkiye (TUR) | G34: =+'Group Stage Predictions'!G32 -> 1 | J34: =+IF(ISBLANK('Group Stage Predictions'!E63)," ",'Group Stage Predictions'!AQ121) -> SWE | K34: 3CDFGH
B35: =+'Group Stage Predictions'!B33 -> 46192.542 | C35: =+'Group Stage Predictions'!C33 -> Seattle | D35: =+'Group Stage Predictions'!D33 -> USA | E35: =+'Group Stage Predictions'!E33 -> 1 | F35: =+'Group Stage Predictions'!F33 -> Australia (AUS) | G35: =+'Group Stage Predictions'!G33 -> 0
B36: =+'Group Stage Predictions'!B34 -> 46192.875 | C36: =+'Group Stage Predictions'!C34 -> San Francisco | D36: =+'Group Stage Predictions'!D34 -> Türkiye (TUR) | E36: =+'Group Stage Predictions'!E34 -> 0 | F36: =+'Group Stage Predictions'!F34 -> Paraguay (PAR) | G36: =+'Group Stage Predictions'!G34 -> 0 | N36: 45852.542 | O36: FRA
B37: =+'Group Stage Predictions'!B35 -> 46198.833 | C37: =+'Group Stage Predictions'!C35 -> Los Angeles | D37: =+'Group Stage Predictions'!D35 -> Türkiye (TUR) | E37: =+'Group Stage Predictions'!E35 -> 0 | F37: =+'Group Stage Predictions'!F35 -> USA | G37: =+'Group Stage Predictions'!G35 -> 1 | J37: =+IF(ISBLANK('Group Stage Predictions'!E31)," ",+'Group Stage Predictions'!K32) -> USA | K37: 1D | N37: Dallas
B38: =+'Group Stage Predictions'!B36 -> 46198.833 | C38: =+'Group Stage Predictions'!C36 -> San Francisco | D38: =+'Group Stage Predictions'!D36 -> Paraguay (PAR) | E38: =+'Group Stage Predictions'!E36 -> 0 | F38: =+'Group Stage Predictions'!F36 -> Australia (AUS) | G38: =+'Group Stage Predictions'!G36 -> 0 | I38: 45839.75
I39: San Francisco | L39: USA
B40: GROUP E
B41: =+'Group Stage Predictions'!B39 -> 46187.458 | C41: =+'Group Stage Predictions'!C39 -> Houston | D41: =+'Group Stage Predictions'!D39 -> Germany (GER) | E41: =+'Group Stage Predictions'!E39 -> 5 | F41: =+'Group Stage Predictions'!F39 -> Curaçao (CUW) | G41: =+'Group Stage Predictions'!G39 -> 0 | J41: =+IF(ISBLANK('Group Stage Predictions'!E7)," ",'Group Stage Predictions'!AN121) -> BIH | K41: 3BEFIJ
B42: =+'Group Stage Predictions'!B40 -> 46187.792 | C42: =+'Group Stage Predictions'!C40 -> Philadelphia | D42: =+'Group Stage Predictions'!D40 -> Côte d'Ivoire (CIV) | E42: =+'Group Stage Predictions'!E40 -> 0 | F42: =+'Group Stage Predictions'!F40 -> Ecuador (ECU) | G42: =+'Group Stage Predictions'!G40 -> 1 | L42: 43287.75
...

Sheet For Organiser
A1: Entrant | B1: Team | C1: Stage | D1: Group | E1: Pick ID | F1: Team A | G1: Team A Goals | H1: Team B | I1: Team B Goals | J1: Chosen team
A2: ='Knock-Out Predictions'!$N$3 -> Edward Sherrington | B2: ='Knock-Out Predictions'!$N$4 -> 3 Lions on the Jersey | C2: Group stage | D2: A | E2: GS-01 | F2: ='Knock-Out Predictions'!D9 -> Mexico (MEX) | G2: ='Knock-Out Predictions'!E9 -> 1 | H2: ='Knock-Out Predictions'!F9 -> South Africa (RSA) | I2: ='Knock-Out Predictions'!G9 -> 0
A3: ='Knock-Out Predictions'!$N$3 -> Edward Sherrington | B3: ='Knock-Out Predictions'!$N$4 -> 3 Lions on the Jersey | C3: Group stage | D3: A | E3: GS-02 | F3: ='Knock-Out Predictions'!D10 -> Korea Republic (KOR) | G3: ='Knock-Out Predictions'!E10 -> 0 | H3: ='Knock-Out Predictions'!F10 -> Czechia (CZE) | I3: ='Knock-Out Predictions'!G10 -> 0
A4: ='Knock-Out Predictions'!$N$3 -> Edward Sherrington | B4: ='Knock-Out Predictions'!$N$4 -> 3 Lions on the Jersey | C4: Group stage | D4: A | E4: GS-03 | F4: ='Knock-Out Predictions'!D11 -> Mexico (MEX) | G4: ='Knock-Out Predictions'!E11 -> 1 | H4: ='Knock-Out Predictions'!F11 -> Korea Republic (KOR) | I4: ='Knock-Out Predictions'!G11 -> 0
A5: ='Knock-Out Predictions'!$N$3 -> Edward Sherrington | B5: ='Knock-Out Predictions'!$N$4 -> 3 Lions on the Jersey | C5: Group stage | D5: A | E5: GS-04 | F5: ='Knock-Out Predictions'!D12 -> Czechia (CZE) | G5: ='Knock-Out Predictions'!E12 -> 0 | H5: ='Knock-Out Predictions'!F12 -> South Africa (RSA) | I5: ='Knock-Out Predictions'!G12 -> 0
A6: ='Knock-Out Predictions'!$N$3 -> Edward Sherrington | B6: ='Knock-Out Predictions'!$N$4 -> 3 Lions on the Jersey | C6: Group stage | D6: A | E6: GS-05 | F6: ='Knock-Out Predictions'!D13 -> Czechia (CZE) | G6: ='Knock-Out Predictions'!E13 -> 0 | H6: ='Knock-Out Predictions'!F13 -> Mexico (MEX) | I6: ='Knock-Out Predictions'!G13 -> 1
A7: ='Knock-Out Predictions'!$N$3 -> Edward Sherrington | B7: ='Knock-Out Predictions'!$N$4 -> 3 Lions on the Jersey | C7: Group stage | D7: A | E7: GS-06 | F7: ='Knock-Out Predictions'!D14 -> South Africa (RSA) | G7: ='Knock-Out Predictions'!E14 -> 0 | H7: ='Knock-Out Predictions'!F14 -> Korea Republic (KOR) | I7: ='Knock-Out Predictions'!G14 -> 1
A8: ='Knock-Out Predictions'!$N$3 -> Edward Sherrington | B8: ='Knock-Out Predictions'!$N$4 -> 3 Lions on the Jersey | C8: Group stage | D8: B | E8: GS-07 | F8: ='Knock-Out Predictions'!D17 -> Canada (CAN) | G8: ='Knock-Out Predictions'!E17 -> 1 | H8: ='Knock-Out Predictions'!F17 -> Bosnia and Herzegovina (BIH) | I8: ='Knock-Out Predictions'!G17 -> 0
A9: ='Knock-Out Predictions'!$N$3 -> Edward Sherrington | B9: ='Knock-Out Predictions'!$N$4 -> 3 Lions on the Jersey | C9: Group stage | D9: B | E9: GS-08 | F9: ='Knock-Out Predictions'!D18 -> Qatar (QAT) | G9: ='Knock-Out Predictions'!E18 -> 0 | H9: ='Knock-Out Predictions'!F18 -> Switzerland (SUI) | I9: ='Knock-Out Predictions'!G18 -> 2
A10: ='Knock-Out Predictions'!$N$3 -> Edward Sherrington | B10: ='Knock-Out Predictions'!$N$4 -> 3 Lions on the Jersey | C10: Group stage | D10: B | E10: GS-09 | F10: ='Knock-Out Predictions'!D19 -> Canada (CAN) | G10: ='Knock-Out Predictions'!E19 -> 1 | H10: ='Knock-Out Predictions'!F19 -> Qatar (QAT) | I10: ='Knock-Out Predictions'!G19 -> 0
A11: ='Knock-Out Predictions'!$N$3 -> Edward Sherrington | B11: ='Knock-Out Predictions'!$N$4 -> 3 Lions on the Jersey | C11: Group stage | D11: B | E11: GS-10 | F11: ='Knock-Out Predictions'!D20 -> Switzerland (SUI) | G11: ='Knock-Out Predictions'!E20 -> 1 | H11: ='Knock-Out Predictions'!F20 -> Bosnia and Herzegovina (BIH) | I11: ='Knock-Out Predictions'!G20 -> 0
